<?xml version="1.0" ?>
<!-- =================================================================================== -->
<!-- |    This document was autogenerated by xacro from robot.xacro                    | -->
<!-- |    EDITING THIS FILE BY HAND IS NOT RECOMMENDED                                 | -->
<!-- =================================================================================== -->
<robot name="DobotCR5">
	<link name="base_link">
		<inertial>
			<origin xyz="-8.0961E-06 0.0019103 0.028995"/>
			<mass value="0.90882"/>
			<inertia ixx="0.0014545" ixy="4.2968E-08" ixz="-1.8199E-07" iyy="0.001345" iyz="-6.243E-06" izz="0.002155"/>
		</inertial>
		<visual>
			<geometry>
				<mesh filename="visual/base_link.obj"/>
			</geometry>
		</visual>
		<collision>
			<geometry>
				<mesh filename="collision/base_link.obj"/>
			</geometry>
		</collision>
	</link>
	<link name="Link1">
		<inertial>
			<origin xyz="-8.7268E-07 -0.0032576 -0.0076748"/>
			<mass value="1.6123"/>
			<inertia ixx="0.0029122" ixy="5.7387E-09" ixz="1.9945E-08" iyy="0.0028191" iyz="0.00044094" izz="0.0032836"/>
		</inertial>
		<visual>
			<geometry>
				<mesh filename="visual/Link1.obj"/>
			</geometry>
		</visual>
		<collision>
			<geometry>
				<mesh filename="collision/Link1_0.obj"/>
			</geometry>
		</collision>
		<collision>
			<geometry>
				<mesh filename="collision/Link1_1.obj"/>
			</geometry>
		</collision>
	</link>
	<joint name="joint1" type="revolute">
		<origin xyz="0 0 0.147"/>
		<parent link="base_link"/>
		<child link="Link1"/>
		<axis xyz="0 0 1"/>
		<limit effort="300" lower="-6.28318" upper="6.28318" velocity="3.14159"/>
	</joint>
	<link name="Link2">
		<inertial>
			<origin xyz="-0.21351 -1.3842E-06 0.14252"/>
			<mass value="5.5186"/>
			<inertia ixx="0.0085919" ixy="7.5552E-07" ixz="-7.8922E-07" iyy="0.027553" iyz="1.4629E-07" izz="0.028294"/>
		</inertial>
		<visual>
			<geometry>
				<mesh filename="visual/Link2.obj"/>
			</geometry>
		</visual>
		<collision>
			<geometry>
				<mesh filename="collision/Link2_0.obj"/>
			</geometry>
		</collision>
		<collision>
			<geometry>
				<mesh filename="collision/Link2_1.obj"/>
			</geometry>
		</collision>
		<collision>
			<geometry>
				<mesh filename="collision/Link2_2.obj"/>
			</geometry>
		</collision>
	</link>
	<joint name="joint2" type="revolute">
		<origin rpy="1.5708 1.5708 0"/>
		<parent link="Link1"/>
		<child link="Link2"/>
		<axis xyz="0 0 1"/>
		<limit effort="300" lower="-6.28318" upper="6.28318" velocity="3.14159"/>
	</joint>
	<link name="Link3">
		<inertial>
			<origin xyz="-0.15231 -1.4079E-07 0.022693"/>
			<mass value="2.8536"/>
			<inertia ixx="0.0032608" ixy="-3.2147E-10" ixz="0.00012363" iyy="0.0092967" iyz="2.9478E-10" izz="0.0095552"/>
		</inertial>
		<visual>
			<geometry>
				<mesh filename="visual/Link3.obj"/>
			</geometry>
		</visual>
		<collision>
			<geometry>
				<mesh filename="collision/Link3_0.obj"/>
			</geometry>
		</collision>
		<collision>
			<geometry>
				<mesh filename="collision/Link3_1.obj"/>
			</geometry>
		</collision>
		<collision>
			<geometry>
				<mesh filename="collision/Link3_2.obj"/>
			</geometry>
		</collision>
	</link>
	<joint name="joint3" type="revolute">
		<origin xyz="-0.427 0 0"/>
		<parent link="Link2"/>
		<child link="Link3"/>
		<axis xyz="0 0 1"/>
		<limit effort="300" lower="-2.7925" upper="2.7925" velocity="3.14159"/>
	</joint>
	<link name="Link4">
		<inertial>
			<origin xyz="-3.2386E-07 -0.002077 -0.0015548"/>
			<mass value="0.67058"/>
			<inertia ixx="0.00066939" ixy="4.1975E-10" ixz="-1.0734E-08" iyy="0.00065424" iyz="0.00011081" izz="0.00065365"/>
		</inertial>
		<visual>
			<geometry>
				<mesh filename="visual/Link4.obj"/>
			</geometry>
		</visual>
		<collision>
			<geometry>
				<mesh filename="collision/Link4_0.obj"/>
			</geometry>
		</collision>
		<collision>
			<geometry>
				<mesh filename="collision/Link4_1.obj"/>
			</geometry>
		</collision>
	</link>
	<joint name="joint4" type="revolute">
		<origin rpy="0 0 -1.5708" xyz="-0.357 0 0.141"/>
		<parent link="Link3"/>
		<child link="Link4"/>
		<axis xyz="0 0 1"/>
		<limit effort="300" lower="-6.28318" upper="6.28318" velocity="3.14159"/>
	</joint>
	<link name="Link5">
		<inertial>
			<origin xyz="-3.7738E-07 -0.0045777 -0.0012971"/>
			<mass value="0.7269"/>
			<inertia ixx="0.00073069" ixy="-5.7806E-09" ixz="6.7132E-09" iyy="0.00071195" iyz="-0.00011926" izz="0.00071391"/>
		</inertial>
		<visual>
			<geometry>
				<mesh filename="visual/Link5.obj"/>
			</geometry>
		</visual>
		<collision>
			<geometry>
				<mesh filename="collision/Link5.obj"/>
			</geometry>
		</collision>
	</link>
	<joint name="joint5" type="revolute">
		<origin rpy="1.5708 0 0" xyz="0 -0.116 0"/>
		<parent link="Link4"/>
		<child link="Link5"/>
		<axis xyz="0 0 1"/>
		<limit effort="300" lower="-6.28318" upper="6.28318" velocity="3.14159"/>
	</joint>
	<link name="Link6">
		<inertial>
			<origin xyz="5.0777E-11 9.3774E-05 -0.019285"/>
			<mass value="0.15789"/>
			<inertia ixx="7.8045E-05" ixy="6.1582E-15" ixz="6.2471E-14" iyy="7.9168E-05" iyz="-1.3822E-07" izz="0.00012951"/>
		</inertial>
		<visual>
			<geometry>
				<mesh filename="visual/Link6.obj"/>
			</geometry>
		</visual>
		<collision>
			<geometry>
				<mesh filename="collision/Link6.obj"/>
			</geometry>
		</collision>
	</link>
	<joint name="joint6" type="revolute">
		<origin rpy="-1.5708 0 0" xyz="0 0.105 0"/>
		<parent link="Link5"/>
		<child link="Link6"/>
		<axis xyz="0 0 1"/>
		<limit effort="300" lower="-6.28318" upper="6.28318" velocity="3.14159"/>
	</joint>
	<joint name="gripper_fix" type="fixed">
		<parent link="Link6"/>
		<child link="flange"/>
		<origin rpy="0 0 1.5707963267948966"/>
	</joint>
	<link name="flange">
		<inertial>
			<origin xyz="-0.000388 0.002345 0.0"/>
			<mass value="0.114"/>
			<inertia ixx="0.000040105" ixy="0.000000214" ixz="0.0" iyy="0.000085776" iyz="0.0" izz="0.000054044"/>
		</inertial>
		<visual>
			<geometry>
				<mesh filename="../../../grippers/ChangingTek/AG2F90-C/flange.obj"/>
			</geometry>
		</visual>
		<collision>
			<geometry>
				<mesh filename="../../../grippers/ChangingTek/AG2F90-C/flange.obj"/>
			</geometry>
		</collision>
	</link>
	<joint name="flange_joint" type="fixed">
		<origin xyz="0 0 0.0195"/>
		<parent link="flange"/>
		<child link="gripper_base"/>
	</joint>
	<link name="gripper_base">
		<inertial>
			<origin xyz="3.45207417426861E-05 -0.000141443719270944 0.0415526970475172"/>
			<mass value="0.310447980489903"/>
			<inertia ixx="0.000404388005636034" ixy="-6.8589621466727E-08" ixz="5.84928727366459E-08"
			         iyy="0.000296494720930083" iyz="-1.79342738400452E-07" izz="0.000212447969282029"/>
		</inertial>
		<visual>
			<geometry>
				<mesh filename="../../../grippers/ChangingTek/AG2F90-C/gripper_base.obj"/>
			</geometry>
		</visual>
		<collision>
			<geometry>
				<mesh filename="../../../grippers/ChangingTek/AG2F90-C/gripper_base.obj"/>
			</geometry>
		</collision>
	</link>
	<link name="left_1_link">
		<inertial>
			<origin xyz="-1.28088127539536E-18 0.0252734640095115 -0.00214040614650292"/>
			<mass value="0.0129014357535444"/>
			<inertia ixx="3.35976482443235E-06" ixy="-3.3181849198807E-25" ixz="-3.35726667613063E-23"
			         iyy="1.65185846940368E-07" iyz="2.63476012977044E-07" izz="3.25394125032869E-06"/>
		</inertial>
		<visual>
			<geometry>
				<mesh filename="../../../grippers/ChangingTek/AG2F90-C/link_1.obj"/>
			</geometry>
		</visual>
		<collision>
			<geometry>
				<mesh filename="../../../grippers/ChangingTek/AG2F90-C/link_1.obj"/>
			</geometry>
		</collision>
	</link>
	<joint name="gripper_joint" type="revolute">
		<origin rpy="1.5708 0 0" xyz="0 -0.030141 0.090147"/>
		<parent link="gripper_base"/>
		<child link="left_1_link"/>
		<axis xyz="1 0 0"/>
		<limit effort="1000" lower="0" upper="1" velocity="2.0"/>
	</joint>
	<link name="left_up_link">
		<inertial>
			<origin xyz="8.69802213948566E-11 0.0124078988097444 -0.0072525614743534"/>
			<mass value="0.014692561982481"/>
			<inertia ixx="2.35283034039115E-06" ixy="3.49796352982052E-14" ixz="-4.72158842036621E-15"
			         iyy="5.8942945477579E-07" iyz="7.05860796345956E-07" izz="2.07228020361883E-06"/>
		</inertial>
		<visual>
			<geometry>
				<mesh filename="../../../grippers/ChangingTek/AG2F90-C/up_link.obj"/>
			</geometry>
		</visual>
		<collision>
			<geometry>
				<mesh filename="../../../grippers/ChangingTek/AG2F90-C/up_link.obj"/>
			</geometry>
		</collision>
	</link>
	<joint name="left_up_Joint" type="revolute">
		<origin xyz="0 0.054804 -0.0046413"/>
		<parent link="left_1_link"/>
		<child link="left_up_link"/>
		<axis xyz="-1 0 0"/>
		<limit effort="1000" lower="0" upper="1" velocity="2.0"/>
		<mimic joint="gripper_joint" multiplier="1" offset="0"/>
	</joint>
	<link name="left_Pad_link">
		<inertial>
			<origin xyz="-3.83777509579761E-08 0.00303135276101582 0.0028336970357949"/>
			<mass value="0.0183171479595721"/>
			<inertia ixx="2.35683098270332E-06" ixy="-4.7353365844279E-12" ixz="-9.31433971475514E-13"
			         iyy="9.08136064346118E-07" iyz="-1.55873132053129E-08" izz="3.18448591439082E-06"/>
		</inertial>
		<visual>
			<geometry>
				<mesh filename="../../../grippers/ChangingTek/AG2F90-C/pad_link.obj"/>
			</geometry>
		</visual>
		<collision>
			<geometry>
				<mesh filename="../../../grippers/ChangingTek/AG2F90-C/pad_link.obj"/>
			</geometry>
		</collision>
	</link>
	<joint name="left_Pad_Joint" type="fixed">
		<origin xyz="0 0.04125 -0.02425"/>
		<parent link="left_up_link"/>
		<child link="left_Pad_link"/>
	</joint>
	<link name="left_2_link">
		<inertial>
			<origin xyz="5.08224485200288E-06 0.0327050710040551 -0.00276963392800038"/>
			<mass value="0.0188752657753052"/>
			<inertia ixx="3.4145090175335E-06" ixy="-3.3317063785682E-22" ixz="-8.3582474326843E-22"
			         iyy="2.86837057727488E-07" iyz="2.64809197911117E-07" izz="3.39111483394506E-06"/>
		</inertial>
		<visual>
			<geometry>
				<mesh filename="../../../grippers/ChangingTek/AG2F90-C/link_2.obj"/>
			</geometry>
		</visual>
		<collision>
			<geometry>
				<mesh filename="../../../grippers/ChangingTek/AG2F90-C/link_2.obj"/>
			</geometry>
		</collision>
	</link>
	<joint name="left_2_Joint" type="revolute">
		<origin rpy="1.5708 0 0" xyz="0 -0.016 0.107"/>
		<parent link="gripper_base"/>
		<child link="left_2_link"/>
		<axis xyz="1 0 0"/>
		<limit effort="1000" lower="0" upper="1" velocity="2.0"/>
		<mimic joint="gripper_joint" multiplier="1" offset="0"/>
	</joint>
	<link name="right_2_link">
		<inertial>
			<origin xyz="1.94651792710713E-17 0.0327174794493866 -0.00277053098700989"/>
			<mass value="0.0188856364479881"/>
			<inertia ixx="3.41458781978465E-06" ixy="2.85152078238725E-22" ixz="9.8903086622122E-22"
			         iyy="2.86883124998043E-07" iyz="2.64817198026894E-07" izz="3.39114800103702E-06"/>
		</inertial>
		<visual>
			<geometry>
				<mesh filename="../../../grippers/ChangingTek/AG2F90-C/link_2.obj"/>
			</geometry>
		</visual>
		<collision>
			<geometry>
				<mesh filename="../../../grippers/ChangingTek/AG2F90-C/link_2.obj"/>
			</geometry>
		</collision>
	</link>
	<joint name="right_2_Joint" type="revolute">
		<origin rpy="1.5708 0 3.1416" xyz="0 0.016 0.107"/>
		<parent link="gripper_base"/>
		<child link="right_2_link"/>
		<axis xyz="1 0 0"/>
		<limit effort="1000" lower="0" upper="1" velocity="2.0"/>
		<mimic joint="gripper_joint" multiplier="1" offset="0"/>
	</joint>
	<link name="right_1_link">
		<inertial>
			<origin xyz="-5.25233292439781E-19 0.0252734640095115 -0.00214040614650291"/>
			<mass value="0.0129014357535444"/>
			<inertia ixx="3.35976482443235E-06" ixy="-3.94978742494071E-23" ixz="-2.72484926002331E-23"
			         iyy="1.65185846940368E-07" iyz="2.63476012977044E-07" izz="3.25394125032869E-06"/>
		</inertial>
		<visual>
			<geometry>
				<mesh filename="../../../grippers/ChangingTek/AG2F90-C/link_1.obj"/>
			</geometry>
		</visual>
		<collision>
			<geometry>
				<mesh filename="../../../grippers/ChangingTek/AG2F90-C/link_1.obj"/>
			</geometry>
		</collision>
	</link>
	<joint name="right_1_Joint" type="revolute">
		<origin rpy="1.5708 0 3.1416" xyz="0 0.030141 0.090147"/>
		<parent link="gripper_base"/>
		<child link="right_1_link"/>
		<axis xyz="1 0 0"/>
		<limit effort="1000" lower="0" upper="1" velocity="2.0"/>
		<mimic joint="gripper_joint" multiplier="1" offset="0"/>
	</joint>
	<link name="right_up_link">
		<inertial>
			<origin xyz="8.69814518862609E-11 0.0124078988097266 -0.00725256147435587"/>
			<mass value="0.014692561982481"/>
			<inertia ixx="2.35283034039115E-06" ixy="3.49796366331572E-14" ixz="-4.72158801523363E-15"
			         iyy="5.89429454773258E-07" iyz="7.05860796343296E-07" izz="2.07228020362137E-06"/>
		</inertial>
		<visual>
			<geometry>
				<mesh filename="../../../grippers/ChangingTek/AG2F90-C/up_link.obj"/>
			</geometry>
		</visual>
		<collision>
			<geometry>
				<mesh filename="../../../grippers/ChangingTek/AG2F90-C/up_link.obj"/>
			</geometry>
		</collision>
	</link>
	<joint name="right_up_Joint" type="revolute">
		<origin xyz="0 0.054804 -0.0046413"/>
		<parent link="right_1_link"/>
		<child link="right_up_link"/>
		<axis xyz="-1 0 0"/>
		<limit effort="1000" lower="0" upper="1" velocity="2.0"/>
		<mimic joint="gripper_joint" multiplier="1" offset="0"/>
	</joint>
	<link name="right_Pad_link">
		<inertial>
			<origin xyz="-3.83777509579761E-08 0.00303135276101582 0.0028336970357949"/>
			<mass value="0.0183171479595721"/>
			<inertia ixx="2.35683098270332E-06" ixy="-4.7353365844279E-12" ixz="-9.31433971475514E-13"
			         iyy="9.08136064346118E-07" iyz="-1.55873132053129E-08" izz="3.18448591439082E-06"/>
		</inertial>
		<visual>
			<geometry>
				<mesh filename="../../../grippers/ChangingTek/AG2F90-C/pad_link.obj"/>
			</geometry>
		</visual>
		<collision>
			<geometry>
				<mesh filename="../../../grippers/ChangingTek/AG2F90-C/pad_link.obj"/>
			</geometry>
		</collision>
	</link>
	<joint name="right_Pad_Joint" type="fixed">
		<origin xyz="0 0.04125 -0.02425"/>
		<parent link="right_up_link"/>
		<child link="right_Pad_link"/>
	</joint>
	<link name="eef"/>
	<joint name="eef_joint" type="fixed">
		<parent link="gripper_base"/>
		<child link="eef"/>
		<origin xyz="0 0 0.19"/>
	</joint>
</robot>
