<?xml version='1.0' encoding='utf-8'?>
<robot name="fanuc_lrmate200id7l">
  <link name="world" />
  <joint name="world_fixed" type="fixed">
    <parent link="world" />
    <child link="base" />
  </joint>
  <link name="base" />
  <joint name="base_link-base" type="fixed">
    <origin xyz="0 0 0.0" rpy="0 0 0" />
    <parent link="base" />
    <child link="base_link" />
  </joint>
  <link name="base_link">
    <inertial>
      <origin xyz="-0.073983 0.00022734 0.13031" rpy="0 0 0" />
      <mass value="42.212" />
      <inertia ixx="0.64296" ixy="0.0012624" ixz="-0.068804" iyy="1.2709" iyz="-0.0010754" izz="1.3497" />
    </inertial>
    <visual>
      <origin xyz="0 0 0" rpy="0 0 0" />
      <geometry>
        <mesh filename="../../third_party/Robot_Digital_Twin/gazebo/meshes/lrmate200id_7L/base_link.stl" />
      </geometry>
      <material name="">
        <color rgba="0.278431372549 0.278431372549 0.278431372549 1.0" />
      </material>
    </visual>
    <collision>
      <origin xyz="0 0 0" rpy="0 0 0" />
      <geometry>
        <mesh filename="../../third_party/Robot_Digital_Twin/gazebo/meshes/lrmate200id_7L/base_link.stl" />
      </geometry>
    </collision>
  </link>
  <link name="link_1">
    <inertial>
      <origin xyz="0.058962 0.24363 -0.018725" rpy="0 0 0" />
      <mass value="37.265" />
      <inertia ixx="0.95018" ixy="-0.14402" ixz="-0.064915" iyy="1.0578" iyz="0.037699" izz="1.094" />
    </inertial>
    <visual>
      <origin xyz="0 0 0" rpy="0 0 0" />
      <geometry>
        <mesh filename="../../third_party/Robot_Digital_Twin/gazebo/meshes/lrmate200id_7L/link_1.stl" />
      </geometry>
      <material name="">
        <color rgba="0.96 0.76 0.13 1.0" />
      </material>
    </visual>
    <collision>
      <origin xyz="0 0 0" rpy="0 0 0" />
      <geometry>
        <mesh filename="../../third_party/Robot_Digital_Twin/gazebo/meshes/lrmate200id_7L/link_1.stl" />
      </geometry>
    </collision>
  </link>
  <link name="link_2">
    <inertial>
      <origin xyz="3.5083E-05 0.39008 0.15036" rpy="0 0 0" />
      <mass value="22.632" />
      <inertia ixx="1.7745" ixy="-0.0054743" ixz="0.00063015" iyy="0.15511" iyz="-0.09224" izz="1.826" />
    </inertial>
    <visual>
      <origin xyz="0 0 0" rpy="0 0 0" />
      <geometry>
        <mesh filename="../../third_party/Robot_Digital_Twin/gazebo/meshes/lrmate200id_7L/link_2.stl" />
      </geometry>
      <material name="">
        <color rgba="0.96 0.76 0.13 1.0" />
      </material>
    </visual>
    <collision>
      <origin xyz="0 0 0" rpy="0 0 0" />
      <geometry>
        <mesh filename="../../third_party/Robot_Digital_Twin/gazebo/meshes/lrmate200id_7L/link_2.stl" />
      </geometry>
    </collision>
  </link>
  <link name="link_3">
    <inertial>
      <origin xyz="0.086423 0.14427 -0.035793" rpy="0 0 0" />
      <mass value="28.467" />
      <inertia ixx="0.65771" ixy="-0.13627" ixz="-0.026219" iyy="0.52683" iyz="0.051956" izz="0.69722" />
    </inertial>
    <visual>
      <origin xyz="0 0 0" rpy="0 0 0" />
      <geometry>
        <mesh filename="../../third_party/Robot_Digital_Twin/gazebo/meshes/lrmate200id_7L/link_3.stl" />
      </geometry>
      <material name="">
        <color rgba="0.96 0.76 0.13 1.0" />
      </material>
    </visual>
    <collision>
      <origin xyz="0 0 0" rpy="0 0 0" />
      <geometry>
        <mesh filename="../../third_party/Robot_Digital_Twin/gazebo/meshes/lrmate200id_7L/link_3.stl" />
      </geometry>
    </collision>
  </link>
  <link name="link_4">
    <inertial>
      <origin xyz="0.37337 0.00033491 0.012656" rpy="0 0 0" />
      <mass value="7.629" />
      <inertia ixx="0.018151" ixy="-0.00033527" ixz="-0.031589" iyy="0.48072" iyz="3.3917E-05" izz="0.47647" />
    </inertial>
    <visual>
      <origin xyz="0 0 0" rpy="0 0 0" />
      <geometry>
        <mesh filename="../../third_party/Robot_Digital_Twin/gazebo/meshes/lrmate200id_7L/link_4.stl" />
      </geometry>
      <material name="">
        <color rgba="0.96 0.76 0.13 1.0" />
      </material>
    </visual>
    <collision>
      <origin xyz="0 0 0" rpy="0 0 0" />
      <geometry>
        <mesh filename="../../third_party/Robot_Digital_Twin/gazebo/meshes/lrmate200id_7L/link_4.stl" />
      </geometry>
    </collision>
  </link>
  <link name="link_5">
    <inertial>
      <origin xyz="0.062818 3.3289E-05 0.0048991" rpy="0 0 0" />
      <mass value="2.5794" />
      <inertia ixx="0.015161" ixy="-2.4835E-06" ixz="0.0016647" iyy="0.021382" iyz="-2.248E-06" izz="0.013473" />
    </inertial>
    <visual>
      <origin xyz="0 0 0" rpy="0 0 0" />
      <geometry>
        <mesh filename="../../third_party/Robot_Digital_Twin/gazebo/meshes/lrmate200id_7L/link_5.stl" />
      </geometry>
      <material name="">
        <color rgba="0.96 0.76 0.13 1.0" />
      </material>
    </visual>
    <collision>
      <origin xyz="0 0 0" rpy="0 0 0" />
      <geometry>
        <mesh filename="../../third_party/Robot_Digital_Twin/gazebo/meshes/lrmate200id_7L/link_5.stl" />
      </geometry>
    </collision>
  </link>
  <link name="link_6">
    <inertial>
      <origin xyz="0.00015982 -0.00063018 -0.008266" rpy="0 0 0" />
      <mass value="0.10811" />
      <inertia ixx="9.0129E-05" ixy="-1.0891E-08" ixz="9.1598E-09" iyy="9.2026E-05" iyz="-2.749E-07" izz="0.00017818" />
    </inertial>
    <visual>
      <origin xyz="0 0 0" rpy="0 0 0" />
      <geometry>
        <mesh filename="../../third_party/Robot_Digital_Twin/gazebo/meshes/lrmate200id_7L/link_6.stl" />
      </geometry>
      <material name="">
        <color rgba="0.15 0.15 0.15 1.0" />
      </material>
    </visual>
    <collision>
      <origin xyz="0 0 0" rpy="0 0 0" />
      <geometry>
        <mesh filename="../../third_party/Robot_Digital_Twin/gazebo/meshes/lrmate200id_7L/link_6.stl" />
      </geometry>
    </collision>
  </link>
  <link name="fts">
    <collision>
      <origin xyz="0 0 0" rpy=" 0 0 0" />
      <geometry>
        <cylinder length="0.041" radius="0.035" />
      </geometry>
    </collision>
    <visual>
      <origin xyz="0 0 0" rpy="0 0 0" />
      <geometry>
        <cylinder length="0.041" radius="0.035" />
      </geometry>
    </visual>
    <inertial>
      <mass value="1e-5" />
      <origin xyz="0 0 0" rpy="0 0 0" />
      <inertia ixx="1e-6" ixy="0" ixz="0" iyy="1e-6" iyz="0" izz="1e-6" />
    </inertial>
  </link>
  <link name="link_tool">
    <inertial>
      <origin xyz="0 0 0" rpy="0 0 0" />
      <mass value="0.10811" />
      <inertia ixx="9.0129E-05" ixy="-1.0891E-08" ixz="9.1598E-09" iyy="9.2026E-05" iyz="-2.749E-07" izz="0.00017818" />
    </inertial>
    <visual>
      <origin xyz="0 0 0" rpy="0 0 0" />
      <geometry>
        <mesh filename="../../third_party/Robot_Digital_Twin/gazebo/meshes/eoat/tool_base.stl" />
      </geometry>
      <material name="">
        <color rgba="0.15 0.15 0.15 1.0" />
      </material>
    </visual>
  </link>
  <link name="link_precam">
    <inertial>
      <mass value="1e-5" />
      <origin xyz="0 0 0" rpy="0 0 0" />
      <inertia ixx="1e-6" ixy="0" ixz="0" iyy="1e-6" iyz="0" izz="1e-6" />
    </inertial>
  </link>
  <link name="link_camera">
    <inertial>
      <origin xyz="0 0 0" rpy="0 0 0" />
      <mass value="0.10811" />
      <inertia ixx="9.0129E-05" ixy="-1.0891E-08" ixz="9.1598E-09" iyy="9.2026E-05" iyz="-2.749E-07" izz="0.00017818" />
    </inertial>
    <visual>
      <origin xyz="0 0 0" rpy="0 0 0" />
      <geometry>
        <mesh filename="../../third_party/Robot_Digital_Twin/gazebo/meshes/eoat/L515.stl" />
      </geometry>
      <material name="">
        <color rgba="0.15 0.15 0.15 1.0" />
      </material>
    </visual>
    <collision>
      <origin xyz="0 0 0" rpy="0 0 0" />
      <geometry>
        <mesh filename="../../third_party/Robot_Digital_Twin/gazebo/meshes/eoat/L515.stl" />
      </geometry>
    </collision>
  </link>
  <link name="link_camera_origin">
    <collision>
      <origin xyz="0 0 0" rpy="0 0 0" />
      <geometry>
        <box size="0.0001 0.0001 0.0001" />
      </geometry>
    </collision>
    <visual>
      <origin xyz="0 0 0" rpy="0 0 0" />
      <geometry>
        <box size="0.0001 0.01 0.01" />
      </geometry>
    </visual>
    <inertial>
      <mass value="1e-5" />
      <origin xyz="0 0 0" rpy="0 0 0" />
      <inertia ixx="1e-6" ixy="0" ixz="0" iyy="1e-6" iyz="0" izz="1e-6" />
    </inertial>
  </link>
  <joint name="joint_1" type="continuous">
    <origin xyz="0 0 0.330" rpy="0 0 0" />
    <parent link="base_link" />
    <child link="link_1" />
    <axis xyz="0 0 1" />
  </joint>
  <joint name="joint_2" type="continuous">
    <origin xyz="0.050 0 0" rpy="0 0 0" />
    <parent link="link_1" />
    <child link="link_2" />
    <axis xyz="0 1 0" />
  </joint>
  <joint name="joint_3" type="continuous">
    <origin xyz="0 0 0.440" rpy="0 0 0" />
    <parent link="link_2" />
    <child link="link_3" />
    <axis xyz="0 -1 0" />
  </joint>
  <joint name="joint_4" type="continuous">
    <origin xyz="0 0 0.035" rpy="0 0 0" />
    <parent link="link_3" />
    <child link="link_4" />
    <axis xyz="-1 0 0" />
  </joint>
  <joint name="joint_5" type="continuous">
    <origin xyz="0.420 0 0" rpy="0 0 0" />
    <parent link="link_4" />
    <child link="link_5" />
    <axis xyz="0 -1 0" />
  </joint>
  <joint name="joint_6" type="continuous">
    <origin xyz="0.080 0 0" rpy="0 0 0" />
    <parent link="link_5" />
    <child link="link_6" />
    <axis xyz="-1 0 0" />
  </joint>
  <joint name="link_6_fts" type="fixed">
    <origin xyz="0.02185 0 0" rpy="0 1.57079632679 0" />
    <parent link="link_6" />
    <child link="fts" />
  </joint>
  <joint name="fts_tool" type="revolute">
    <origin xyz="0 0 0.02185" rpy="0 0 3.14159265359" />
    <parent link="fts" />
    <child link="link_tool" />
    <axis xyz="0 0 1" />
    <limit velocity="0" effort="0" lower="0" upper="0" />
  </joint>
  <joint name="tool_precam" type="fixed">
    <origin xyz="0 -0.062194148 -0.005909903" rpy="1.57079632679 -1.57079632679  0" />
    <parent link="link_tool" />
    <child link="link_precam" />
  </joint>
  <joint name="precam_camera" type="fixed">
    <origin xyz="0 0 0" rpy="0 0.785398163397 0" />
    <parent link="link_precam" />
    <child link="link_camera" />
  </joint>
  <joint name="camera_imgplane" type="fixed">
    <origin xyz="0.013 0.0 0.0305" rpy="0 0 0" />
    <parent link="link_camera" />
    <child link="link_camera_origin" />
  </joint>
  <transmission name="trans_joint_1">
    <type>transmission_interface/SimpleTransmission</type>
    <joint name="joint_1">
      <hardwareInterface>hardware_interface/PositionJointInterface</hardwareInterface>
    </joint>
    <actuator name="joint_1_motor">
      <hardwareInterface>hardware_interface/PositionJointInterface</hardwareInterface>
      <mechanicalReduction>1</mechanicalReduction>
    </actuator>
  </transmission>
  <transmission name="trans_joint_2">
    <type>transmission_interface/SimpleTransmission</type>
    <joint name="joint_2">
      <hardwareInterface>hardware_interface/PositionJointInterface</hardwareInterface>
    </joint>
    <actuator name="joint_2_motor">
      <hardwareInterface>hardware_interface/PositionJointInterface</hardwareInterface>
      <mechanicalReduction>1</mechanicalReduction>
    </actuator>
  </transmission>
  <transmission name="trans_joint_3">
    <type>transmission_interface/SimpleTransmission</type>
    <joint name="joint_3">
      <hardwareInterface>hardware_interface/PositionJointInterface</hardwareInterface>
    </joint>
    <actuator name="joint_3_motor">
      <hardwareInterface>hardware_interface/PositionJointInterface</hardwareInterface>
      <mechanicalReduction>1</mechanicalReduction>
    </actuator>
  </transmission>
  <transmission name="trans_joint_4">
    <type>transmission_interface/SimpleTransmission</type>
    <joint name="joint_4">
      <hardwareInterface>hardware_interface/PositionJointInterface</hardwareInterface>
    </joint>
    <actuator name="joint_4_motor">
      <hardwareInterface>hardware_interface/PositionJointInterface</hardwareInterface>
      <mechanicalReduction>1</mechanicalReduction>
    </actuator>
  </transmission>
  <transmission name="trans_joint_5">
    <type>transmission_interface/SimpleTransmission</type>
    <joint name="joint_5">
      <hardwareInterface>hardware_interface/PositionJointInterface</hardwareInterface>
    </joint>
    <actuator name="joint_5_motor">
      <hardwareInterface>hardware_interface/PositionJointInterface</hardwareInterface>
      <mechanicalReduction>1</mechanicalReduction>
    </actuator>
  </transmission>
  <transmission name="trans_joint_6">
    <type>transmission_interface/SimpleTransmission</type>
    <joint name="joint_6">
      <hardwareInterface>hardware_interface/PositionJointInterface</hardwareInterface>
    </joint>
    <actuator name="joint_6_motor">
      <hardwareInterface>hardware_interface/PositionJointInterface</hardwareInterface>
      <mechanicalReduction>1</mechanicalReduction>
    </actuator>
  </transmission>
  <gazebo>
    <plugin name="gazebo_ros_control" filename="libgazebo_ros_control.so">
      <robotSimType>gazebo_ros_control/DefaultRobotHWSim</robotSimType>
      <legacyModeNS>true</legacyModeNS>
    </plugin>
  </gazebo>
  <gazebo reference="fts_tool">
    <provideFeedback>true</provideFeedback>
  </gazebo>
  <gazebo>
    <provideFeedback>true</provideFeedback>
    <plugin name="ft_sensor" filename="libgazebo_ros_ft_sensor.so">
      <alwaysOn> true </alwaysOn>
      <updateRate>125.0</updateRate>
      <topicName>ft_sensor</topicName>
      <jointName>fts_tool</jointName>
      <noise>
        <type>gaussian</type>
        <mean>0.0</mean>
        <stddev>0.001</stddev>
      </noise>
    </plugin>
  </gazebo>
  <gazebo reference="link_camera_origin">
    <sensor name="$depth_camera" type="depth">
      <update_rate>30</update_rate>
      <camera>
        <horizontal_fov>1.22173</horizontal_fov>
        <image>
          <width>1920</width>
          <height>1080</height>
          <format>R8G8B8</format>
        </image>
        <clip>
          <near>0.01</near>
          <far>2</far>
        </clip>
      </camera>
      <plugin name="$depth_camera_controller" filename="libgazebo_ros_openni_kinect.so">
        <baseline>0.2</baseline>
        <alwaysOn>true</alwaysOn>
        <updateRate>0</updateRate>
        <cameraName>wrist_camera</cameraName>
        <frameName>depth_camera_link</frameName>
        <pointCloudCutoff>0.25</pointCloudCutoff>
        <pointCloudCutoffMax>2.0</pointCloudCutoffMax>
        <distortionK1>0</distortionK1>
        <distortionK2>0</distortionK2>
        <distortionK3>0</distortionK3>
        <distortionT1>0</distortionT1>
        <distortionT2>0</distortionT2>
        <CxPrime>0</CxPrime>
        <Cx>0</Cx>
        <Cy>0</Cy>
        <focalLength>0</focalLength>
        <hackBaseline>0</hackBaseline>
      </plugin>
    </sensor>
  </gazebo>
  <gazebo reference="link_1">
    <material>Gazebo/Yellow</material>
    <visual>
      <transparency> 0 </transparency>
    </visual>
  </gazebo>
  <gazebo reference="link_2">
    <material>Gazebo/Yellow</material>
    <visual>
      <transparency> 0 </transparency>
    </visual>
  </gazebo>
  <gazebo reference="link_3">
    <material>Gazebo/Yellow</material>
    <visual>
      <transparency> 0 </transparency>
    </visual>
  </gazebo>
  <gazebo reference="link_4">
    <material>Gazebo/Yellow</material>
    <visual>
      <transparency> 0 </transparency>
    </visual>
  </gazebo>
  <gazebo reference="link_5">
    <material>Gazebo/Yellow</material>
    <visual>
      <transparency> 0 </transparency>
    </visual>
  </gazebo>
  <gazebo reference="link_6">
    <material>Gazebo/Black</material>
    <visual>
      <transparency> 0 </transparency>
    </visual>
  </gazebo>
  <gazebo reference="base_link">
    <material>Gazebo/Yellow</material>
    <visual>
      <transparency> 0 </transparency>
    </visual>
  </gazebo>
  <gazebo reference="link_tool0">
    <material>Gazebo/Black</material>
    <visual>
      <transparency> 0 </transparency>
    </visual>
  </gazebo>
  <gazebo reference="fts">
    <material>Gazebo/Black</material>
    <visual>
      <transparency> 0 </transparency>
    </visual>
  </gazebo>
  <gazebo reference="link_camera_origin">
    <material>Gazebo/Black</material>
    <visual>
      <transparency> 0 </transparency>
    </visual>
  </gazebo>
</robot>