<?xml version='1.0' encoding='utf-8'?>
<robot name="RM75B_with_Gripper_LegoTool">
  <link name="base_link">
    <inertial>
      <origin xyz="0.00049987 5.2709E-05 0.060019" rpy="0 0 0" />
      <mass value="1.862" />
      <inertia ixx="0.0017232" ixy="-3.1058E-06" ixz="-3.7924E-05" iyy="0.0017051" iyz="1.3691E-06" izz="0.00090158" />
    </inertial>
    <visual>
      <geometry>
        <mesh filename="../meshes/base_link.dae" />
      </geometry>
      <material name="">
        <color rgba="1 1 1 1" />
      </material>
    </visual>
    <collision>
      <geometry>
        <mesh filename="../meshes/base_link.dae" />
      </geometry>
    </collision>
  </link>
  <link name="link_1">
    <inertial>
      <origin rpy="0 0 0" xyz="-0.002 0.02692 -0.01332" />
      <mass value="2.16" />
      <inertia ixx="0.00539427" ixy="1.095E-05" ixz="1.635E-06" iyy="0.0048979" iyz="0.000793" izz="0.00311573" />
    </inertial>
    <visual>
      <geometry>
        <mesh filename="../meshes/link_1.dae" />
      </geometry>
    </visual>
    <collision>
      <geometry>
        <mesh filename="../meshes/link_1.dae" />
      </geometry>
    </collision>
  </link>
  <joint name="joint_1" type="revolute">
    <origin xyz="0 0 0.2405" rpy="0 0 0" />
    <parent link="base_link" />
    <child link="link_1" />
    <axis xyz="0 0 1" />
    <limit lower="-3.106" upper="3.106" effort="60" velocity="3.14" />
  </joint>
  <link name="link_2">
    <inertial>
      <origin rpy="0 0 0" xyz="0.03531 -0.21398 0.03386" />
      <mass value="1.71" />
      <inertia ixx="0.0248674" ixy="-0.00430651" ixz="-0.00067797" iyy="0.00485548" iyz="0.00457245" izz="0.02387827" />
    </inertial>
    <visual>
      <geometry>
        <mesh filename="../meshes/link_2.dae" />
      </geometry>
    </visual>
    <collision>
      <geometry>
        <mesh filename="../meshes/link_2.dae" />
      </geometry>
    </collision>
  </link>
  <joint name="joint_2" type="revolute">
    <origin xyz="0 0 0" rpy="-1.5708 0 0" />
    <parent link="link_1" />
    <child link="link_2" />
    <axis xyz="0 0 1" />
    <limit lower="-2.2689" upper="2.2689" effort="60" velocity="3.14" />
  </joint>
  <link name="link_3">
    <inertial>
      <origin rpy="0 0 0" xyz="0.06781 0.10749 0.01457" />
      <mass value="1.384" />
      <inertia ixx="0.0053694" ixy="0.0014185" ixz="-0.00092094" iyy="0.0032423" iyz="-0.00169178" izz="0.00501731" />
    </inertial>
    <visual>
      <geometry>
        <mesh filename="../meshes/link_3.dae" />
      </geometry>
    </visual>
    <collision>
      <geometry>
        <mesh filename="../meshes/link_3.dae" />
      </geometry>
    </collision>
  </link>
  <joint name="joint_3" type="revolute">
    <origin xyz="0 -0.1525 0" rpy="1.5708 0 0" />
    <parent link="link_2" />
    <child link="link_3" />
    <axis xyz="0 0 1" />
    <limit lower="-3.106" upper="3.106" effort="30" velocity="3.14" />
  </joint>
  <link name="link_4">
    <inertial>
      <origin rpy="0 0 0" xyz="-0.00021 0.02578 -0.02538" />
      <mass value="1.115" />
      <inertia ixx="0.00439263" ixy="5.028E-05" ixz="1.374E-05" iyy="0.0040077" iyz="0.00045338" izz="0.00110321" />
    </inertial>
    <visual>
      <geometry>
        <mesh filename="../meshes/link_4.dae" />
      </geometry>
    </visual>
    <collision>
      <geometry>
        <mesh filename="../meshes/link_4.dae" />
      </geometry>
    </collision>
  </link>
  <joint name="joint_4" type="revolute">
    <origin xyz="0 0 0.1035" rpy="-1.5708 0 0" />
    <parent link="link_3" />
    <child link="link_4" />
    <axis xyz="0 0 1" />
    <limit lower="-2.356" upper="2.356" effort="30" velocity="3.14" />
  </joint>
  <link name="link_5">
    <inertial>
      <origin rpy="0 0 0" xyz="0.05428 0.01781 0.00543" />
      <mass value="1.275" />
      <inertia ixx="0.001202758" ixy="0.000492428" ixz="-0.00039147" iyy="0.0022876" iyz="-1.235E-04" izz="0.0026866" />
    </inertial>
    <visual>
      <geometry>
        <mesh filename="../meshes/link_5.dae" />
      </geometry>
    </visual>
    <collision>
      <geometry>
        <mesh filename="../meshes/link_5.dae" />
      </geometry>
    </collision>
  </link>
  <joint name="joint_5" type="revolute">
    <origin xyz="0 -0.21 0" rpy="1.5708 0 0" />
    <parent link="link_4" />
    <child link="link_5" />
    <axis xyz="0 0 1" />
    <limit lower="-3.106" upper="3.106" effort="10" velocity="3.14" />
  </joint>
  <link name="link_6">
    <inertial>
      <origin rpy="0 0 0" xyz="0 0.00064 -0.00952" />
      <mass value="0.1096" />
      <inertia ixx="4.5293E-05" ixy="0" ixz="0" iyy="4.8111E-05" iyz="0" izz="7.9715E-05" />
    </inertial>
    <visual>
      <geometry>
        <mesh filename="../meshes/link_6.dae" />
      </geometry>
    </visual>
    <collision>
      <geometry>
        <mesh filename="../meshes/link_6.dae" />
      </geometry>
    </collision>
  </link>
  <joint name="joint_6" type="revolute">
    <origin xyz="0 0 0" rpy="-1.5708 0 0" />
    <parent link="link_5" />
    <child link="link_6" />
    <axis xyz="0 0 1" />
    <limit lower="-2.234" upper="2.234" effort="10" velocity="3.14" />
  </joint>
  <link name="link_7">
    <inertial>
      <origin xyz="0.001094 -0.000077 -0.010119" rpy="0 0 0" />
      <mass value="0.107" />
      <inertia ixx="0.000044123" ixy="-0.000000064" ixz="0.0000003" iyy="0.000035078" iyz="-0.000000029" izz="0.000065445" />
    </inertial>
    <visual>
      <geometry>
        <mesh filename="../meshes/link_7.dae" />
      </geometry>
      <material name="arm_gray">
        <color rgba="0.5137254901960784 0.5137254901960784 0.5137254901960784 1" />
      </material>
    </visual>
    <collision>
      <geometry>
        <mesh filename="../meshes/link_7.dae" />
      </geometry>
    </collision>
  </link>
  <joint name="joint_7" type="revolute">
    <origin xyz="0 -0.144 0" rpy="1.5708 0 0" />
    <parent link="link_6" />
    <child link="link_7" />
    <axis xyz="0 0 1" />
    <limit lower="-6.28" upper="6.28" effort="10" velocity="3.14" />
  </joint>
  <link name="flange_spacer_8mm">
    <inertial>
      <origin xyz="0 0 0.004000" rpy="0 0 0" />
      <mass value="0.050000" />
      <inertia ixx="1.55791666667e-05" ixy="0" ixz="0" iyy="1.55791666667e-05" iyz="0" izz="3.0625e-05" />
    </inertial>
    <visual>
      <origin xyz="0 0 0.004000" rpy="0 0 0" />
      <geometry>
        <cylinder radius="0.037500" length="0.008000" />
      </geometry>
      <material name="arm_gray">
        <color rgba="0.5137254901960784 0.5137254901960784 0.5137254901960784 1" />
      </material>
    </visual>
    <collision>
      <origin xyz="0 0 0.004000" rpy="0 0 0" />
      <geometry>
        <cylinder radius="0.037500" length="0.008000" />
      </geometry>
    </collision>
  </link>
  <joint name="link7_to_flange_spacer_8mm" type="fixed">
    <origin xyz="0 0 0" rpy="0 0 0.5236" />
    <parent link="link_7" />
    <child link="flange_spacer_8mm" />
  </joint>
  <link name="lego_tool_link">
    <inertial>
      <origin xyz="0 0 0" rpy="0 0 0" />
      <mass value="0.050000" />
      <inertia ixx="3e-05" ixy="0" ixz="0" iyy="3e-05" iyz="0" izz="3e-05" />
    </inertial>
    <visual>
      <origin xyz="0.109847 -0.021913 0.111532" rpy="1.57079632679 0 3.14159265359" />
      <geometry>
        <mesh filename="../meshes/lego_test_open_fixed.stl" scale="0.001 0.001 0.001" />
      </geometry>
      <material name="lego_tool_gray">
        <color rgba="0.55 0.55 0.55 0.65" />
      </material>
    </visual>
    <collision>
      <origin xyz="0.109847 -0.021913 0.111532" rpy="1.57079632679 0 3.14159265359" />
      <geometry>
        <mesh filename="../meshes/lego_test_open_fixed.stl" scale="0.001 0.001 0.001" />
      </geometry>
    </collision>
  </link>
  <joint name="flange_spacer_8mm_to_lego_tool" type="fixed">
    <origin xyz="0 0 0.008000" rpy="0 0 0" />
    <parent link="flange_spacer_8mm" />
    <child link="lego_tool_link" />
  </joint>
  <link name="lego_tool_tcp" />
  <joint name="lego_tool_tcp_joint" type="fixed">
    <origin xyz="0 0 0.075000" rpy="0 0 0" />
    <parent link="lego_tool_link" />
    <child link="lego_tool_tcp" />
  </joint>
</robot>
