<?xml version="1.0" encoding="utf-8"?>
<robot name="RM75B_with_Gripper">

  <link name="base_link">
    <inertial>
      <origin rpy="0 0 0" xyz="0.00049987 5.2709E-05 0.060019"/>
      <mass value="1.862"/>
      <inertia ixx="0.0017232" ixy="-3.1058E-06" ixz="-3.7924E-05" iyy="0.0017051" iyz="1.3691E-06" izz="0.00090158"/>
    </inertial>
    <visual>
      <geometry><mesh filename="../meshes/base_link.STL"/></geometry>
      <material name=""><color rgba="1 1 1 1"/></material>
    </visual>
    <collision>
      <geometry><mesh filename="vhacd_collision/base_link.obj"/></geometry>
    </collision>
  </link>

  <link name="link_1">
    <inertial>
      <origin rpy="0 0 0" xyz="0 0.02 -0.01"/>
      <mass value="1.5"/>
      <inertia ixx="0.005" ixy="0" ixz="0" iyy="0.005" iyz="0" izz="0.003"/>
    </inertial>
    <visual><geometry><mesh filename="../meshes/link_1.STL"/></geometry></visual>
    <collision><geometry><mesh filename="vhacd_collision/link_1.obj"/></geometry></collision>
  </link>
  <joint name="joint_1" type="revolute">
    <origin rpy="0 0 0" xyz="0 0 0.2405"/>
    <parent link="base_link"/><child link="link_1"/>
    <axis xyz="0 0 1"/>
    <safety_controller k_position="100.0" k_velocity="40.0" soft_lower_limit="-3.106" soft_upper_limit="3.106"/>
    <limit effort="60" lower="-3.106" upper="3.106" velocity="3.14"/>
    <dynamics damping="1.0" friction="1.0"/>
  </joint>

  <link name="link_2">
    <inertial>
      <origin rpy="0 0 0" xyz="0 -0.12 0"/>
      <mass value="1.8"/>
      <inertia ixx="0.02" ixy="0" ixz="0" iyy="0.004" iyz="0" izz="0.02"/>
    </inertial>
    <visual><geometry><mesh filename="../meshes/link_2.STL"/></geometry></visual>
    <collision><geometry><mesh filename="vhacd_collision/link_2.obj"/></geometry></collision>
  </link>
  <joint name="joint_2" type="revolute">
    <origin rpy="-1.5708 0 0" xyz="0 0 0"/>
    <parent link="link_1"/><child link="link_2"/>
    <axis xyz="0 0 1"/>
    <safety_controller k_position="100.0" k_velocity="40.0" soft_lower_limit="-2.2689" soft_upper_limit="2.2689"/>
    <limit effort="60" lower="-2.2689" upper="2.2689" velocity="3.14"/>
    <dynamics damping="1.0" friction="1.0"/>
  </joint>

  <link name="link_3">
    <inertial>
      <origin rpy="0 0 0" xyz="0 0.05 0"/>
      <mass value="1.2"/>
      <inertia ixx="0.004" ixy="0" ixz="0" iyy="0.003" iyz="0" izz="0.004"/>
    </inertial>
    <visual><geometry><mesh filename="../meshes/link_3.STL"/></geometry></visual>
    <collision><geometry><mesh filename="vhacd_collision/link_3.obj"/></geometry></collision>
  </link>
  <joint name="joint_3" type="revolute">
    <origin rpy="1.5708 0 0" xyz="0 -0.256 0"/>
    <parent link="link_2"/><child link="link_3"/>
    <axis xyz="0 0 1"/>
    <safety_controller k_position="100.0" k_velocity="40.0" soft_lower_limit="-3.106" soft_upper_limit="3.106"/>
    <limit effort="30" lower="-3.106" upper="3.106" velocity="3.14"/>
    <dynamics damping="1.0" friction="1.0"/>
  </joint>

  <link name="link_4">
    <inertial>
      <origin rpy="0 0 0" xyz="0 0.02 -0.02"/>
      <mass value="1.0"/>
      <inertia ixx="0.004" ixy="0" ixz="0" iyy="0.003" iyz="0" izz="0.001"/>
    </inertial>
    <visual><geometry><mesh filename="../meshes/link_4.STL"/></geometry></visual>
    <collision><geometry><mesh filename="vhacd_collision/link_4.obj"/></geometry></collision>
  </link>
  <joint name="joint_4" type="revolute">
    <origin rpy="-1.5708 0 0" xyz="0 0 0"/>
    <parent link="link_3"/><child link="link_4"/>
    <axis xyz="0 0 1"/>
    <safety_controller k_position="100.0" k_velocity="40.0" soft_lower_limit="-2.356" soft_upper_limit="2.356"/>
    <limit effort="30" lower="-2.356" upper="2.356" velocity="3.14"/>
    <dynamics damping="1.0" friction="1.0"/>
  </joint>

  <link name="link_5">
    <inertial>
      <origin rpy="0 0 0" xyz="0 -0.1 0"/>
      <mass value="0.8"/>
      <inertia ixx="0.003" ixy="0" ixz="0" iyy="0.001" iyz="0" izz="0.003"/>
    </inertial>
    <visual><geometry><mesh filename="../meshes/link_5.STL"/></geometry></visual>
    <collision><geometry><mesh filename="vhacd_collision/link_5.obj"/></geometry></collision>
  </link>
  <joint name="joint_5" type="revolute">
    <origin rpy="1.5708 0 0" xyz="0 -0.21 0"/>
    <parent link="link_4"/><child link="link_5"/>
    <axis xyz="0 0 1"/>
    <safety_controller k_position="100.0" k_velocity="40.0" soft_lower_limit="-3.106" soft_upper_limit="3.106"/>
    <limit effort="10" lower="-3.106" upper="3.106" velocity="3.14"/>
    <dynamics damping="1.0" friction="1.0"/>
  </joint>

  <link name="link_6">
    <inertial>
      <origin rpy="0 0 0" xyz="0 0 -0.01"/>
      <mass value="0.5"/>
      <inertia ixx="0.001" ixy="0" ixz="0" iyy="0.001" iyz="0" izz="0.0005"/>
    </inertial>
    <visual><geometry><mesh filename="../meshes/link_6.STL"/></geometry></visual>
    <collision><geometry><mesh filename="vhacd_collision/link_6.obj"/></geometry></collision>
  </link>
  <joint name="joint_6" type="revolute">
    <origin rpy="-1.5708 0 0" xyz="0 0 0"/>
    <parent link="link_5"/><child link="link_6"/>
    <axis xyz="0 0 1"/>
    <safety_controller k_position="100.0" k_velocity="40.0" soft_lower_limit="-2.234" soft_upper_limit="2.234"/>
    <limit effort="10" lower="-2.234" upper="2.234" velocity="3.14"/>
    <dynamics damping="1.0" friction="1.0"/>
  </joint>

  <link name="link_7">
    <inertial>
      <origin rpy="0 0 0" xyz="0.001094 -0.000077 -0.010119"/>
      <mass value="0.107"/>
      <inertia ixx="0.000044123" ixy="-0.000000064" ixz="0.0000003" iyy="0.000035078" iyz="-0.000000029" izz="0.000065445"/>
    </inertial>
    <visual><geometry><mesh filename="../meshes/link_7.STL"/></geometry></visual>
    <collision><geometry><mesh filename="vhacd_collision/link_7.obj"/></geometry></collision>
  </link>
  <joint name="joint_7" type="revolute">
    <origin rpy="1.5708 0 0" xyz="0 -0.144 0"/>
    <parent link="link_6"/><child link="link_7"/>
    <axis xyz="0 0 1"/>
    <safety_controller k_position="100.0" k_velocity="40.0" soft_lower_limit="-6.28" soft_upper_limit="6.28"/>
    <limit effort="10" lower="-6.28" upper="6.28" velocity="3.14"/>
    <dynamics damping="1.0" friction="1.0"/>
  </joint>

  <joint name="arm_gripper_joint" type="fixed">
    <origin rpy="0 0 0.5236" xyz="0 0 0"/>
    <parent link="link_7"/>
    <child link="gripper_base"/>
  </joint>

  <link name="gripper_base">
    <inertial>
      <origin rpy="0 0 0" xyz="0 0 0"/>
      <mass value="0.001"/>
      <inertia ixx="0.000001" ixy="0" ixz="0" iyy="0.000001" iyz="0" izz="0.000001"/>
    </inertial>
  </link>

  <link name="gripper_base_link">
    <inertial>
      <origin rpy="0 0 0" xyz="0 0 0.05"/>
      <mass value="0.2"/>
      <inertia ixx="0.0002" ixy="0" ixz="0" iyy="0.0002" iyz="0" izz="0.0001"/>
    </inertial>
    <visual>
      <geometry><mesh filename="../../crt_ctag2f90d_gripper_visualization/meshes/base_link.STL"/></geometry>
      <material name=""><color rgba="0.615686274509804 0.63921568627451 0.674509803921569 1"/></material>
    </visual>
    <collision><geometry><mesh filename="vhacd_collision/gripper_base_link.obj"/></geometry></collision>
  </link>
  <joint name="gripper_base_link_Joint" type="fixed">
    <origin rpy="0 0 0" xyz="0 0 0"/>
    <parent link="gripper_base"/>
    <child link="gripper_base_link"/>
  </joint>

  <link name="eef"/>
  <joint name="eef_joint" type="fixed">
    <parent link="gripper_base_link"/>
    <child link="eef"/>
    <origin xyz="0 0 0.12" rpy="0 0 0"/>
  </joint>

  <link name="gripper_Left_1_Link">
    <inertial>
      <origin rpy="0 0 0" xyz="0.02 0.02 0"/>
      <mass value="0.05"/>
      <inertia ixx="0.00002" ixy="0" ixz="0" iyy="0.00002" iyz="0" izz="0.00001"/>
    </inertial>
    <visual><geometry><mesh filename="../../crt_ctag2f90d_gripper_visualization/meshes/Left_1_Link.STL"/></geometry></visual>
    <collision><geometry><mesh filename="vhacd_collision/gripper_Left_1_Link.obj"/></geometry></collision>
  </link>
  <joint name="gripper_Left_1_Joint" type="revolute">
    <origin rpy="1.5708 0 0" xyz="0.030141 0 0.10415"/>
    <parent link="gripper_base_link"/><child link="gripper_Left_1_Link"/>
    <axis xyz="0 0 1"/>
    <limit effort="1000" lower="0" upper="0.91" velocity="2.0"/>
  </joint>

  <link name="gripper_Left_Support_Link">
    <inertial>
      <origin rpy="0 0 0" xyz="-0.01 0.03 0"/>
      <mass value="0.03"/>
      <inertia ixx="0.00001" ixy="0" ixz="0" iyy="0.00002" iyz="0" izz="0.00001"/>
    </inertial>
    <visual><geometry><mesh filename="../../crt_ctag2f90d_gripper_visualization/meshes/Left_Support_Link.STL"/></geometry></visual>
    <collision><geometry><mesh filename="vhacd_collision/gripper_Left_Support_Link.obj"/></geometry></collision>
  </link>
  <joint name="gripper_Left_Support_Joint" type="revolute">
    <origin rpy="0 0 0" xyz="0.040359 0.037365 0"/>
    <parent link="gripper_Left_1_Link"/><child link="gripper_Left_Support_Link"/>
    <axis xyz="0 0 -1"/>
    <limit effort="1000" lower="0" upper="0.91" velocity="2.0"/>
  </joint>

  <link name="gripper_Left_2_Link">
    <inertial>
      <origin rpy="0 0 0" xyz="0.02 0.02 0"/>
      <mass value="0.03"/>
      <inertia ixx="0.00001" ixy="0" ixz="0" iyy="0.00001" iyz="0" izz="0.000005"/>
    </inertial>
    <visual><geometry><mesh filename="../../crt_ctag2f90d_gripper_visualization/meshes/Left_2_Link.STL"/></geometry></visual>
    <collision><geometry><mesh filename="vhacd_collision/gripper_Left_2_Link.obj"/></geometry></collision>
  </link>
  <joint name="gripper_Left_2_Joint" type="revolute">
    <origin rpy="1.5708 0 0" xyz="0.016 0 0.121"/>
    <parent link="gripper_base_link"/><child link="gripper_Left_2_Link"/>
    <axis xyz="0 0 1"/>
    <limit effort="1000" lower="0" upper="0.91" velocity="2.0"/>
  </joint>

  <link name="gripper_Right_1_Link">
    <inertial>
      <origin rpy="0 0 0" xyz="0.02 0.02 0"/>
      <mass value="0.05"/>
      <inertia ixx="0.00002" ixy="0" ixz="0" iyy="0.00002" iyz="0" izz="0.00001"/>
    </inertial>
    <visual><geometry><mesh filename="../../crt_ctag2f90d_gripper_visualization/meshes/Right_1_Link.STL"/></geometry></visual>
    <collision><geometry><mesh filename="vhacd_collision/gripper_Right_1_Link.obj"/></geometry></collision>
  </link>
  <joint name="gripper_Right_1_Joint" type="revolute">
    <origin rpy="1.5708 0 3.1416" xyz="-0.030141 0 0.10415"/>
    <parent link="gripper_base_link"/><child link="gripper_Right_1_Link"/>
    <axis xyz="0 0 1"/>
    <limit effort="1000" lower="0" upper="0.91" velocity="2.0"/>
  </joint>

  <link name="gripper_Right_Support_Link">
    <inertial>
      <origin rpy="0 0 0" xyz="-0.01 0.03 0"/>
      <mass value="0.03"/>
      <inertia ixx="0.00001" ixy="0" ixz="0" iyy="0.00002" iyz="0" izz="0.00001"/>
    </inertial>
    <visual><geometry><mesh filename="../../crt_ctag2f90d_gripper_visualization/meshes/Right_Support_Link.STL"/></geometry></visual>
    <collision><geometry><mesh filename="vhacd_collision/gripper_Right_Support_Link.obj"/></geometry></collision>
  </link>
  <joint name="gripper_Right_Support_Joint" type="revolute">
    <origin rpy="0 0 0" xyz="0.040359 0.037365 0"/>
    <parent link="gripper_Right_1_Link"/><child link="gripper_Right_Support_Link"/>
    <axis xyz="0 0 -1"/>
    <limit effort="1000" lower="0" upper="0.91" velocity="2.0"/>
  </joint>

  <link name="gripper_Right_2_Link">
    <inertial>
      <origin rpy="0 0 0" xyz="0.02 0.02 0"/>
      <mass value="0.03"/>
      <inertia ixx="0.00001" ixy="0" ixz="0" iyy="0.00001" iyz="0" izz="0.000005"/>
    </inertial>
    <visual><geometry><mesh filename="../../crt_ctag2f90d_gripper_visualization/meshes/Right_2_Link.STL"/></geometry></visual>
    <collision><geometry><mesh filename="vhacd_collision/gripper_Right_2_Link.obj"/></geometry></collision>
  </link>
  <joint name="gripper_Right_2_Joint" type="revolute">
    <origin rpy="1.5708 0 3.1416" xyz="-0.016 0 0.121"/>
    <parent link="gripper_base_link"/><child link="gripper_Right_2_Link"/>
    <axis xyz="0 0 1"/>
    <limit effort="1000" lower="0" upper="0.91" velocity="2.0"/>
  </joint>

  <link name="left_pad">
    <inertial>
      <mass value="0"/>
      <inertia ixx="0.00" ixy="0.00" ixz="0.00" iyy="0.00" iyz="0.00" izz="0.00"/>
    </inertial>
  </link>
  <joint name="left_pad_joint" type="fixed">
    <parent link="gripper_Left_Support_Link"/>
    <child link="left_pad"/>
    <origin rpy="0 0 0" xyz="-0.02 0.055 0"/>
  </joint>

  <link name="right_pad">
    <inertial>
      <mass value="0"/>
      <inertia ixx="0.00" ixy="0.00" ixz="0.00" iyy="0.00" iyz="0.00" izz="0.00"/>
    </inertial>
  </link>
  <joint name="right_pad_joint" type="fixed">
    <parent link="gripper_Right_Support_Link"/>
    <child link="right_pad"/>
    <origin rpy="0 0 0" xyz="-0.02 0.055 0"/>
  </joint>

</robot>
