<?xml version='1.0' encoding='utf-8'?>
<robot name="RM75B_with_Gripper">
  <link name="base_link">
    <inertial>
      <origin xyz="0 0 0" rpy="0 0 0" />
      <mass value="0.001" />
      <inertia ixx="1e-7" ixy="0" ixz="0" iyy="1e-7" iyz="0" izz="1e-7" />
    </inertial>
    <visual>
      <origin xyz="0 0 0" rpy="0 0 0" />
      <geometry>
        <box size="0.008000 0.008000 0.008000" />
      </geometry>
    </visual>
    <collision>
      <origin xyz="0 0 0" rpy="0 0 0" />
      <geometry>
        <box size="0.008000 0.008000 0.008000" />
      </geometry>
    </collision>
  </link>
  <link name="link_1">
    <inertial>
      <origin xyz="0 0 0" rpy="0 0 0" />
      <mass value="0.001" />
      <inertia ixx="1e-7" ixy="0" ixz="0" iyy="1e-7" iyz="0" izz="1e-7" />
    </inertial>
    <visual>
      <origin xyz="0 0 0" rpy="0 0 0" />
      <geometry>
        <box size="0.008000 0.008000 0.008000" />
      </geometry>
    </visual>
    <collision>
      <origin xyz="0 0 0" rpy="0 0 0" />
      <geometry>
        <box size="0.008000 0.008000 0.008000" />
      </geometry>
    </collision>
  </link>
  <link name="link_2">
    <inertial>
      <origin xyz="0 0 0" rpy="0 0 0" />
      <mass value="0.001" />
      <inertia ixx="1e-7" ixy="0" ixz="0" iyy="1e-7" iyz="0" izz="1e-7" />
    </inertial>
    <visual>
      <origin xyz="0 0 0" rpy="0 0 0" />
      <geometry>
        <box size="0.008000 0.008000 0.008000" />
      </geometry>
    </visual>
    <collision>
      <origin xyz="0 0 0" rpy="0 0 0" />
      <geometry>
        <box size="0.008000 0.008000 0.008000" />
      </geometry>
    </collision>
  </link>
  <link name="link_3">
    <inertial>
      <origin xyz="0 0 0" rpy="0 0 0" />
      <mass value="0.001" />
      <inertia ixx="1e-7" ixy="0" ixz="0" iyy="1e-7" iyz="0" izz="1e-7" />
    </inertial>
    <visual>
      <origin xyz="0 0 0" rpy="0 0 0" />
      <geometry>
        <box size="0.008000 0.008000 0.008000" />
      </geometry>
    </visual>
    <collision>
      <origin xyz="0 0 0" rpy="0 0 0" />
      <geometry>
        <box size="0.008000 0.008000 0.008000" />
      </geometry>
    </collision>
  </link>
  <link name="link_4">
    <inertial>
      <origin xyz="0 0 0" rpy="0 0 0" />
      <mass value="0.001" />
      <inertia ixx="1e-7" ixy="0" ixz="0" iyy="1e-7" iyz="0" izz="1e-7" />
    </inertial>
    <visual>
      <origin xyz="0 0 0" rpy="0 0 0" />
      <geometry>
        <box size="0.008000 0.008000 0.008000" />
      </geometry>
    </visual>
    <collision>
      <origin xyz="0 0 0" rpy="0 0 0" />
      <geometry>
        <box size="0.008000 0.008000 0.008000" />
      </geometry>
    </collision>
  </link>
  <link name="link_5">
    <inertial>
      <origin xyz="0 0 0" rpy="0 0 0" />
      <mass value="0.001" />
      <inertia ixx="1e-7" ixy="0" ixz="0" iyy="1e-7" iyz="0" izz="1e-7" />
    </inertial>
    <visual>
      <origin xyz="0 0 0" rpy="0 0 0" />
      <geometry>
        <box size="0.008000 0.008000 0.008000" />
      </geometry>
    </visual>
    <collision>
      <origin xyz="0 0 0" rpy="0 0 0" />
      <geometry>
        <box size="0.008000 0.008000 0.008000" />
      </geometry>
    </collision>
  </link>
  <link name="link_6">
    <inertial>
      <origin xyz="0 0 0" rpy="0 0 0" />
      <mass value="0.001" />
      <inertia ixx="1e-7" ixy="0" ixz="0" iyy="1e-7" iyz="0" izz="1e-7" />
    </inertial>
    <visual>
      <origin xyz="0 0 0" rpy="0 0 0" />
      <geometry>
        <box size="0.010000 0.010000 0.010000" />
      </geometry>
    </visual>
    <collision>
      <origin xyz="0 0 0" rpy="0 0 0" />
      <geometry>
        <box size="0.010000 0.010000 0.010000" />
      </geometry>
    </collision>
  </link>
  <link name="link_7">
    <inertial>
      <origin xyz="0 0 0" rpy="0 0 0" />
      <mass value="0.001" />
      <inertia ixx="1e-7" ixy="0" ixz="0" iyy="1e-7" iyz="0" izz="1e-7" />
    </inertial>
    <visual>
      <origin xyz="0 0 0" rpy="0 0 0" />
      <geometry>
        <box size="0.010000 0.010000 0.010000" />
      </geometry>
    </visual>
    <collision>
      <origin xyz="0 0 0" rpy="0 0 0" />
      <geometry>
        <box size="0.010000 0.010000 0.010000" />
      </geometry>
    </collision>
  </link>
  <link name="gripper_base">
    <inertial>
      <origin xyz="0 0 0" rpy="0 0 0" />
      <mass value="0.001" />
      <inertia ixx="1e-7" ixy="0" ixz="0" iyy="1e-7" iyz="0" izz="1e-7" />
    </inertial>
    <visual>
      <origin xyz="0 0 0" rpy="0 0 0" />
      <geometry>
        <box size="0.005000 0.005000 0.005000" />
      </geometry>
    </visual>
    <collision>
      <origin xyz="0 0 0" rpy="0 0 0" />
      <geometry>
        <box size="0.005000 0.005000 0.005000" />
      </geometry>
    </collision>
  </link>
  <link name="gripper_base_link">
    <inertial>
      <origin xyz="0 0 0" rpy="0 0 0" />
      <mass value="0.001" />
      <inertia ixx="1e-7" ixy="0" ixz="0" iyy="1e-7" iyz="0" izz="1e-7" />
    </inertial>
    <visual>
      <origin xyz="0 0 0" rpy="0 0 0" />
      <geometry>
        <box size="0.005000 0.005000 0.005000" />
      </geometry>
    </visual>
    <collision>
      <origin xyz="0 0 0" rpy="0 0 0" />
      <geometry>
        <box size="0.005000 0.005000 0.005000" />
      </geometry>
    </collision>
  </link>
  <link name="gripper_Left_1_Link">
    <inertial>
      <origin xyz="0 0 0" rpy="0 0 0" />
      <mass value="0.001" />
      <inertia ixx="1e-7" ixy="0" ixz="0" iyy="1e-7" iyz="0" izz="1e-7" />
    </inertial>
    <visual>
      <origin xyz="0 0 0" rpy="0 0 0" />
      <geometry>
        <box size="0.005000 0.005000 0.005000" />
      </geometry>
    </visual>
    <collision>
      <origin xyz="0 0 0" rpy="0 0 0" />
      <geometry>
        <box size="0.005000 0.005000 0.005000" />
      </geometry>
    </collision>
  </link>
  <link name="gripper_Left_Support_Link">
    <inertial>
      <origin xyz="0 0 0" rpy="0 0 0" />
      <mass value="0.001" />
      <inertia ixx="1e-7" ixy="0" ixz="0" iyy="1e-7" iyz="0" izz="1e-7" />
    </inertial>
    <visual>
      <origin xyz="0 0 0" rpy="0 0 0" />
      <geometry>
        <box size="0.005000 0.005000 0.005000" />
      </geometry>
    </visual>
    <collision>
      <origin xyz="0 0 0" rpy="0 0 0" />
      <geometry>
        <box size="0.005000 0.005000 0.005000" />
      </geometry>
    </collision>
  </link>
  <link name="gripper_Left_2_Link">
    <inertial>
      <origin xyz="0 0 0" rpy="0 0 0" />
      <mass value="0.001" />
      <inertia ixx="1e-7" ixy="0" ixz="0" iyy="1e-7" iyz="0" izz="1e-7" />
    </inertial>
    <visual>
      <origin xyz="0 0 0" rpy="0 0 0" />
      <geometry>
        <box size="0.005000 0.005000 0.005000" />
      </geometry>
    </visual>
    <collision>
      <origin xyz="0 0 0" rpy="0 0 0" />
      <geometry>
        <box size="0.005000 0.005000 0.005000" />
      </geometry>
    </collision>
  </link>
  <link name="gripper_Right_1_Link">
    <inertial>
      <origin xyz="0 0 0" rpy="0 0 0" />
      <mass value="0.001" />
      <inertia ixx="1e-7" ixy="0" ixz="0" iyy="1e-7" iyz="0" izz="1e-7" />
    </inertial>
    <visual>
      <origin xyz="0 0 0" rpy="0 0 0" />
      <geometry>
        <box size="0.005000 0.005000 0.005000" />
      </geometry>
    </visual>
    <collision>
      <origin xyz="0 0 0" rpy="0 0 0" />
      <geometry>
        <box size="0.005000 0.005000 0.005000" />
      </geometry>
    </collision>
  </link>
  <link name="gripper_Right_Support_Link">
    <inertial>
      <origin xyz="0 0 0" rpy="0 0 0" />
      <mass value="0.001" />
      <inertia ixx="1e-7" ixy="0" ixz="0" iyy="1e-7" iyz="0" izz="1e-7" />
    </inertial>
    <visual>
      <origin xyz="0 0 0" rpy="0 0 0" />
      <geometry>
        <box size="0.005000 0.005000 0.005000" />
      </geometry>
    </visual>
    <collision>
      <origin xyz="0 0 0" rpy="0 0 0" />
      <geometry>
        <box size="0.005000 0.005000 0.005000" />
      </geometry>
    </collision>
  </link>
  <link name="gripper_Right_2_Link">
    <inertial>
      <origin xyz="0 0 0" rpy="0 0 0" />
      <mass value="0.001" />
      <inertia ixx="1e-7" ixy="0" ixz="0" iyy="1e-7" iyz="0" izz="1e-7" />
    </inertial>
    <visual>
      <origin xyz="0 0 0" rpy="0 0 0" />
      <geometry>
        <box size="0.005000 0.005000 0.005000" />
      </geometry>
    </visual>
    <collision>
      <origin xyz="0 0 0" rpy="0 0 0" />
      <geometry>
        <box size="0.005000 0.005000 0.005000" />
      </geometry>
    </collision>
  </link>
  <link name="left_pad">
    <inertial>
      <origin xyz="0 0 0" rpy="0 0 0" />
      <mass value="0.001" />
      <inertia ixx="1e-7" ixy="0" ixz="0" iyy="1e-7" iyz="0" izz="1e-7" />
    </inertial>
    <visual>
      <origin xyz="0 0 0" rpy="0 0 0" />
      <geometry>
        <box size="0.005000 0.005000 0.005000" />
      </geometry>
    </visual>
    <collision>
      <origin xyz="0 0 0" rpy="0 0 0" />
      <geometry>
        <box size="0.005000 0.005000 0.005000" />
      </geometry>
    </collision>
  </link>
  <link name="right_pad">
    <inertial>
      <origin xyz="0 0 0" rpy="0 0 0" />
      <mass value="0.001" />
      <inertia ixx="1e-7" ixy="0" ixz="0" iyy="1e-7" iyz="0" izz="1e-7" />
    </inertial>
    <visual>
      <origin xyz="0 0 0" rpy="0 0 0" />
      <geometry>
        <box size="0.005000 0.005000 0.005000" />
      </geometry>
    </visual>
    <collision>
      <origin xyz="0 0 0" rpy="0 0 0" />
      <geometry>
        <box size="0.005000 0.005000 0.005000" />
      </geometry>
    </collision>
  </link>
  <link name="flange_spacer_8mm">
    <inertial>
      <origin xyz="0 0 0" rpy="0 0 0" />
      <mass value="0.001" />
      <inertia ixx="1e-7" ixy="0" ixz="0" iyy="1e-7" iyz="0" izz="1e-7" />
    </inertial>
    <visual>
      <origin xyz="0 0 0" rpy="0 0 0" />
      <geometry>
        <box size="0.005000 0.005000 0.005000" />
      </geometry>
    </visual>
    <collision>
      <origin xyz="0 0 0" rpy="0 0 0" />
      <geometry>
        <box size="0.005000 0.005000 0.005000" />
      </geometry>
    </collision>
  </link>
  <link name="gripper_tcp" />
  <joint name="joint_1" type="revolute">
    <origin xyz="0 0 0.2405" rpy="0 0 0" />
    <parent link="base_link" />
    <child link="link_1" />
    <axis xyz="0 0 1" />
    <limit lower="-3.106" upper="3.106" effort="60" velocity="3.14" />
  </joint>
  <joint name="joint_2" type="revolute">
    <origin xyz="0 0 0" rpy="-1.5708 0 0" />
    <parent link="link_1" />
    <child link="link_2" />
    <axis xyz="0 0 1" />
    <limit lower="-2.2689" upper="2.2689" effort="60" velocity="3.14" />
  </joint>
  <joint name="joint_3" type="revolute">
    <origin xyz="0 -0.1525 0" rpy="1.5708 0 0" />
    <parent link="link_2" />
    <child link="link_3" />
    <axis xyz="0 0 1" />
    <limit lower="-3.106" upper="3.106" effort="30" velocity="3.14" />
  </joint>
  <joint name="joint_4" type="revolute">
    <origin xyz="0 0 0.1035" rpy="-1.5708 0 0" />
    <parent link="link_3" />
    <child link="link_4" />
    <axis xyz="0 0 1" />
    <limit lower="-2.356" upper="2.356" effort="30" velocity="3.14" />
  </joint>
  <joint name="joint_5" type="revolute">
    <origin xyz="0 -0.21 0" rpy="1.5708 0 0" />
    <parent link="link_4" />
    <child link="link_5" />
    <axis xyz="0 0 1" />
    <limit lower="-3.106" upper="3.106" effort="10" velocity="3.14" />
  </joint>
  <joint name="joint_6" type="revolute">
    <origin xyz="0 0 0" rpy="-1.5708 0 0" />
    <parent link="link_5" />
    <child link="link_6" />
    <axis xyz="0 0 1" />
    <limit lower="-2.234" upper="2.234" effort="10" velocity="3.14" />
  </joint>
  <joint name="joint_7" type="revolute">
    <origin xyz="0 -0.144 0" rpy="1.5708 0 0" />
    <parent link="link_6" />
    <child link="link_7" />
    <axis xyz="0 0 1" />
    <limit lower="-6.28" upper="6.28" effort="10" velocity="3.14" />
  </joint>
  <joint name="gripper_base_link_Joint" type="fixed">
    <origin xyz="0 0 0" rpy="0 0 0" />
    <parent link="gripper_base" />
    <child link="gripper_base_link" />
  </joint>
  <joint name="gripper_Left_1_Joint" type="fixed">
    <origin xyz="0.030141 0 0.10415" rpy="1.5708 0 0" />
    <parent link="gripper_base_link" />
    <child link="gripper_Left_1_Link" />
  </joint>
  <joint name="gripper_Left_Support_Joint" type="fixed">
    <origin xyz="0.040359 0.037365 0" rpy="0 0 0" />
    <parent link="gripper_Left_1_Link" />
    <child link="gripper_Left_Support_Link" />
  </joint>
  <joint name="gripper_Left_2_Joint" type="fixed">
    <origin xyz="0.016 0 0.121" rpy="1.5708 0 0" />
    <parent link="gripper_base_link" />
    <child link="gripper_Left_2_Link" />
  </joint>
  <joint name="gripper_Right_1_Joint" type="fixed">
    <origin xyz="-0.030141 0 0.10415" rpy="1.5708 0 3.1416" />
    <parent link="gripper_base_link" />
    <child link="gripper_Right_1_Link" />
  </joint>
  <joint name="gripper_Right_Support_Joint" type="fixed">
    <origin xyz="0.040359 0.037365 0" rpy="0 0 0" />
    <parent link="gripper_Right_1_Link" />
    <child link="gripper_Right_Support_Link" />
  </joint>
  <joint name="gripper_Right_2_Joint" type="fixed">
    <origin xyz="-0.016 0 0.121" rpy="1.5708 0 3.1416" />
    <parent link="gripper_base_link" />
    <child link="gripper_Right_2_Link" />
  </joint>
  <joint name="left_pad_joint" type="fixed">
    <parent link="gripper_Left_Support_Link" />
    <child link="left_pad" />
    <origin rpy="0 0 0" xyz="-0.02 0.055 0" />
  </joint>
  <joint name="right_pad_joint" type="fixed">
    <parent link="gripper_Right_Support_Link" />
    <child link="right_pad" />
    <origin rpy="0 0 0" xyz="-0.02 0.055 0" />
  </joint>
  <joint name="link7_to_flange_spacer_8mm" type="fixed">
    <origin xyz="0 0 0" rpy="0 0 0.5236" />
    <parent link="link_7" />
    <child link="flange_spacer_8mm" />
  </joint>
  <joint name="flange_spacer_8mm_to_gripper_base" type="fixed">
    <origin xyz="0 0 0.008000" rpy="0 0 0" />
    <parent link="flange_spacer_8mm" />
    <child link="gripper_base" />
  </joint>
  <joint name="gripper_tcp_joint" type="fixed">
    <origin xyz="0 0 0.2" rpy="0 0 -1.57079632679" />
    <parent link="gripper_base_link" />
    <child link="gripper_tcp" />
  </joint>
</robot>